02/11/20 (09:13:39) | ERROR: Command 'coretemp' returned non-zero exit status 1.
Traceback (most recent call last):
  File "/usr/local/lib/python3.8/site-packages/bpytop.py", line 2820, in _collect_temps
    cores = [max(0, int(x)) for x in subprocess.check_output("coretemp", text=True).split()]
  File "/usr/local/Cellar/python@3.8/3.8.4/Frameworks/Python.framework/Versions/3.8/lib/python3.8/subprocess.py", line 411, in check_output
    return run(*popenargs, stdout=PIPE, timeout=timeout, check=True,
  File "/usr/local/Cellar/python@3.8/3.8.4/Frameworks/Python.framework/Versions/3.8/lib/python3.8/subprocess.py", line 512, in run
    raise CalledProcessError(retcode, process.args,
subprocess.CalledProcessError: Command 'coretemp' returned non-zero exit status 1.
22/11/20 (19:42:32) | ERROR: Command 'coretemp' returned non-zero exit status 1.
Traceback (most recent call last):
  File "/usr/local/lib/python3.8/site-packages/bpytop.py", line 2820, in _collect_temps
    cores = [max(0, int(x)) for x in subprocess.check_output("coretemp", text=True).split()]
  File "/usr/local/Cellar/python@3.8/3.8.4/Frameworks/Python.framework/Versions/3.8/lib/python3.8/subprocess.py", line 411, in check_output
    return run(*popenargs, stdout=PIPE, timeout=timeout, check=True,
  File "/usr/local/Cellar/python@3.8/3.8.4/Frameworks/Python.framework/Versions/3.8/lib/python3.8/subprocess.py", line 512, in run
    raise CalledProcessError(retcode, process.args,
subprocess.CalledProcessError: Command 'coretemp' returned non-zero exit status 1.
30/11/20 (18:00:30) | ERROR: Command 'coretemp' returned non-zero exit status 1.
Traceback (most recent call last):
  File "/usr/local/lib/python3.8/site-packages/bpytop.py", line 2820, in _collect_temps
    cores = [max(0, int(x)) for x in subprocess.check_output("coretemp", text=True).split()]
  File "/usr/local/Cellar/python@3.8/3.8.4/Frameworks/Python.framework/Versions/3.8/lib/python3.8/subprocess.py", line 411, in check_output
    return run(*popenargs, stdout=PIPE, timeout=timeout, check=True,
  File "/usr/local/Cellar/python@3.8/3.8.4/Frameworks/Python.framework/Versions/3.8/lib/python3.8/subprocess.py", line 512, in run
    raise CalledProcessError(retcode, process.args,
subprocess.CalledProcessError: Command 'coretemp' returned non-zero exit status 1.
03/12/20 (23:06:42) | ERROR: Command 'coretemp' returned non-zero exit status 1.
Traceback (most recent call last):
  File "/usr/local/lib/python3.8/site-packages/bpytop.py", line 2820, in _collect_temps
    cores = [max(0, int(x)) for x in subprocess.check_output("coretemp", text=True).split()]
  File "/usr/local/Cellar/python@3.8/3.8.4/Frameworks/Python.framework/Versions/3.8/lib/python3.8/subprocess.py", line 411, in check_output
    return run(*popenargs, stdout=PIPE, timeout=timeout, check=True,
  File "/usr/local/Cellar/python@3.8/3.8.4/Frameworks/Python.framework/Versions/3.8/lib/python3.8/subprocess.py", line 512, in run
    raise CalledProcessError(retcode, process.args,
subprocess.CalledProcessError: Command 'coretemp' returned non-zero exit status 1.
07/12/20 (19:02:15) | ERROR: Command 'coretemp' returned non-zero exit status 1.
Traceback (most recent call last):
  File "/usr/local/lib/python3.8/site-packages/bpytop.py", line 2820, in _collect_temps
    cores = [max(0, int(x)) for x in subprocess.check_output("coretemp", text=True).split()]
  File "/usr/local/Cellar/python@3.8/3.8.4/Frameworks/Python.framework/Versions/3.8/lib/python3.8/subprocess.py", line 411, in check_output
    return run(*popenargs, stdout=PIPE, timeout=timeout, check=True,
  File "/usr/local/Cellar/python@3.8/3.8.4/Frameworks/Python.framework/Versions/3.8/lib/python3.8/subprocess.py", line 512, in run
    raise CalledProcessError(retcode, process.args,
subprocess.CalledProcessError: Command 'coretemp' returned non-zero exit status 1.
12/12/20 (11:42:40) | ERROR: Command 'coretemp' returned non-zero exit status 1.
Traceback (most recent call last):
  File "/usr/local/lib/python3.8/site-packages/bpytop.py", line 2820, in _collect_temps
    cores = [max(0, int(x)) for x in subprocess.check_output("coretemp", text=True).split()]
  File "/usr/local/Cellar/python@3.8/3.8.4/Frameworks/Python.framework/Versions/3.8/lib/python3.8/subprocess.py", line 411, in check_output
    return run(*popenargs, stdout=PIPE, timeout=timeout, check=True,
  File "/usr/local/Cellar/python@3.8/3.8.4/Frameworks/Python.framework/Versions/3.8/lib/python3.8/subprocess.py", line 512, in run
    raise CalledProcessError(retcode, process.args,
subprocess.CalledProcessError: Command 'coretemp' returned non-zero exit status 1.
14/12/20 (21:04:56) | ERROR: Command 'coretemp' returned non-zero exit status 1.
Traceback (most recent call last):
  File "/usr/local/lib/python3.8/site-packages/bpytop.py", line 2820, in _collect_temps
    cores = [max(0, int(x)) for x in subprocess.check_output("coretemp", text=True).split()]
  File "/usr/local/Cellar/python@3.8/3.8.4/Frameworks/Python.framework/Versions/3.8/lib/python3.8/subprocess.py", line 411, in check_output
    return run(*popenargs, stdout=PIPE, timeout=timeout, check=True,
  File "/usr/local/Cellar/python@3.8/3.8.4/Frameworks/Python.framework/Versions/3.8/lib/python3.8/subprocess.py", line 512, in run
    raise CalledProcessError(retcode, process.args,
subprocess.CalledProcessError: Command 'coretemp' returned non-zero exit status 1.
